2021-05-06 10:07:08,794 -- INFO:20 -- Bookmark created, ID: WebSiteBookmark object (9)
2021-05-06 10:08:15,637 -- INFO:20 -- /Users/bolataldiyar/Desktop/password_manager/conf/password_manager/views.py changed, reloading.
2021-05-06 10:08:42,494 -- INFO:20 -- /Users/bolataldiyar/Desktop/password_manager/conf/password_manager/views.py changed, reloading.
2021-05-06 10:09:37,530 -- INFO:20 -- /Users/bolataldiyar/Desktop/password_manager/conf/password_manager/views.py changed, reloading.
2021-05-06 12:24:51,419 -- INFO:20 -- /Users/bolataldiyar/Desktop/password_manager/conf/auth_/__init__.py changed, reloading.
2021-05-06 12:25:01,330 -- WARNING:30 -- Not Acceptable: /auth/create_user
2021-05-06 12:25:29,568 -- INFO:20 -- /Users/bolataldiyar/Desktop/password_manager/conf/auth_/signals.py changed, reloading.
2021-05-06 12:29:36,366 -- INFO:20 -- /Users/bolataldiyar/Desktop/password_manager/conf/auth_/signals.py changed, reloading.
2021-05-06 12:29:36,814 -- INFO:20 -- Watching for file changes with StatReloader
2021-05-06 12:31:34,430 -- INFO:20 -- /Users/bolataldiyar/Desktop/password_manager/conf/auth_/signals.py changed, reloading.
2021-05-06 12:31:34,783 -- INFO:20 -- Watching for file changes with StatReloader
2021-05-06 12:31:51,375 -- WARNING:30 -- Unauthorized: /auth/login/
2021-05-06 12:31:55,400 -- INFO:20 -- token created
2021-05-06 12:32:24,065 -- INFO:20 -- /Users/bolataldiyar/Desktop/password_manager/conf/auth_/signals.py changed, reloading.
2021-05-06 12:32:24,425 -- INFO:20 -- Watching for file changes with StatReloader
2021-05-06 12:32:40,068 -- INFO:20 -- /Users/bolataldiyar/Desktop/password_manager/conf/auth_/signals.py changed, reloading.
2021-05-06 12:32:40,438 -- INFO:20 -- Watching for file changes with StatReloader
2021-05-06 12:33:34,790 -- INFO:20 -- /Users/bolataldiyar/Desktop/password_manager/conf/auth_/signals.py changed, reloading.
2021-05-06 12:33:35,179 -- INFO:20 -- Watching for file changes with StatReloader
2021-05-06 12:33:39,543 -- WARNING:30 -- Unauthorized: /auth/login/
2021-05-06 12:33:54,959 -- INFO:20 -- token deleted
2021-05-06 12:38:41,044 -- INFO:20 -- /Users/bolataldiyar/Desktop/password_manager/conf/auth_/signals.py changed, reloading.
2021-05-06 12:38:41,418 -- INFO:20 -- Watching for file changes with StatReloader
2021-05-06 12:39:20,871 -- INFO:20 -- /Users/bolataldiyar/Desktop/password_manager/conf/auth_/signals.py changed, reloading.
2021-05-06 12:39:21,263 -- INFO:20 -- Watching for file changes with StatReloader
2021-05-06 12:51:05,727 -- INFO:20 -- Watching for file changes with StatReloader
2021-05-06 12:51:41,847 -- WARNING:30 -- Unauthorized: /password_manager/website_password/
2021-05-06 12:52:16,391 -- WARNING:30 -- Unauthorized: /password_manager/website_password/
2021-05-06 12:52:17,724 -- WARNING:30 -- Unauthorized: /password_manager/website_password/
2021-05-06 12:52:18,545 -- WARNING:30 -- Unauthorized: /password_manager/website_password/
2021-05-06 12:54:45,554 -- INFO:20 -- /Users/bolataldiyar/Desktop/password_manager/conf/auth_/signals.py changed, reloading.
2021-05-06 12:54:45,936 -- INFO:20 -- Watching for file changes with StatReloader
2021-05-06 12:55:08,073 -- INFO:20 -- /Users/bolataldiyar/Desktop/password_manager/conf/auth_/signals.py changed, reloading.
2021-05-06 12:55:08,456 -- INFO:20 -- Watching for file changes with StatReloader
2021-05-06 12:56:38,281 -- INFO:20 -- /Users/bolataldiyar/Desktop/password_manager/conf/auth_/signals.py changed, reloading.
2021-05-06 12:56:38,702 -- INFO:20 -- Watching for file changes with StatReloader
2021-05-06 12:57:06,231 -- INFO:20 -- /Users/bolataldiyar/Desktop/password_manager/conf/auth_/signals.py changed, reloading.
2021-05-06 12:57:06,637 -- INFO:20 -- Watching for file changes with StatReloader
2021-05-06 13:00:20,246 -- INFO:20 -- /Users/bolataldiyar/Desktop/password_manager/conf/auth_/signals.py changed, reloading.
2021-05-06 13:00:20,680 -- INFO:20 -- Watching for file changes with StatReloader
2021-05-06 13:16:53,933 -- INFO:20 -- /Users/bolataldiyar/Desktop/password_manager/conf/auth_/models.py changed, reloading.
2021-05-06 13:16:54,358 -- INFO:20 -- Watching for file changes with StatReloader
2021-05-06 13:45:34,424 -- INFO:20 -- /Users/bolataldiyar/Desktop/password_manager/conf/auth_/views.py changed, reloading.
2021-05-06 13:45:34,996 -- INFO:20 -- Watching for file changes with StatReloader
2021-05-06 13:47:42,418 -- INFO:20 -- /Users/bolataldiyar/Desktop/password_manager/conf/auth_/views.py changed, reloading.
2021-05-06 13:47:42,836 -- INFO:20 -- Watching for file changes with StatReloader
2021-05-06 13:47:50,756 -- INFO:20 -- /Users/bolataldiyar/Desktop/password_manager/conf/auth_/views.py changed, reloading.
2021-05-06 13:47:51,094 -- INFO:20 -- Watching for file changes with StatReloader
2021-05-06 13:47:59,074 -- INFO:20 -- /Users/bolataldiyar/Desktop/password_manager/conf/auth_/views.py changed, reloading.
2021-05-06 13:47:59,424 -- INFO:20 -- Watching for file changes with StatReloader
2021-05-06 13:59:29,289 -- INFO:20 -- /Users/bolataldiyar/Desktop/password_manager/conf/auth_/views.py changed, reloading.
2021-05-06 13:59:29,961 -- INFO:20 -- Watching for file changes with StatReloader
2021-05-06 14:00:13,955 -- INFO:20 -- /Users/bolataldiyar/Desktop/password_manager/conf/auth_/views.py changed, reloading.
2021-05-06 14:00:14,350 -- INFO:20 -- Watching for file changes with StatReloader
2021-05-06 14:01:21,753 -- INFO:20 -- /Users/bolataldiyar/Desktop/password_manager/conf/auth_/views.py changed, reloading.
2021-05-06 14:01:22,153 -- INFO:20 -- Watching for file changes with StatReloader
2021-05-06 14:02:11,242 -- INFO:20 -- /Users/bolataldiyar/Desktop/password_manager/conf/auth_/views.py changed, reloading.
2021-05-06 14:02:11,647 -- INFO:20 -- Watching for file changes with StatReloader
2021-05-06 14:03:40,055 -- INFO:20 -- /Users/bolataldiyar/Desktop/password_manager/conf/auth_/urls.py changed, reloading.
2021-05-06 14:03:40,769 -- INFO:20 -- Watching for file changes with StatReloader
2021-05-06 14:05:29,195 -- ERROR:40 -- Internal Server Error: /auth/profile/
Traceback (most recent call last):
  File "/Users/bolataldiyar/Desktop/password_manager/conf/venv/lib/python3.8/site-packages/django/core/handlers/exception.py", line 34, in inner
    response = get_response(request)
  File "/Users/bolataldiyar/Desktop/password_manager/conf/venv/lib/python3.8/site-packages/django/core/handlers/base.py", line 115, in _get_response
    response = self.process_exception_by_middleware(e, request)
  File "/Users/bolataldiyar/Desktop/password_manager/conf/venv/lib/python3.8/site-packages/django/core/handlers/base.py", line 113, in _get_response
    response = wrapped_callback(request, *callback_args, **callback_kwargs)
  File "/Users/bolataldiyar/Desktop/password_manager/conf/venv/lib/python3.8/site-packages/django/views/decorators/csrf.py", line 54, in wrapped_view
    return view_func(*args, **kwargs)
  File "/Users/bolataldiyar/Desktop/password_manager/conf/venv/lib/python3.8/site-packages/rest_framework/viewsets.py", line 125, in view
    return self.dispatch(request, *args, **kwargs)
  File "/Users/bolataldiyar/Desktop/password_manager/conf/venv/lib/python3.8/site-packages/rest_framework/views.py", line 509, in dispatch
    response = self.handle_exception(exc)
  File "/Users/bolataldiyar/Desktop/password_manager/conf/venv/lib/python3.8/site-packages/rest_framework/views.py", line 469, in handle_exception
    self.raise_uncaught_exception(exc)
  File "/Users/bolataldiyar/Desktop/password_manager/conf/venv/lib/python3.8/site-packages/rest_framework/views.py", line 480, in raise_uncaught_exception
    raise exc
  File "/Users/bolataldiyar/Desktop/password_manager/conf/venv/lib/python3.8/site-packages/rest_framework/views.py", line 506, in dispatch
    response = handler(request, *args, **kwargs)
  File "/Users/bolataldiyar/Desktop/password_manager/conf/venv/lib/python3.8/site-packages/rest_framework/mixins.py", line 17, in create
    serializer = self.get_serializer(data=request.data)
  File "/Users/bolataldiyar/Desktop/password_manager/conf/venv/lib/python3.8/site-packages/rest_framework/generics.py", line 108, in get_serializer
    serializer_class = self.get_serializer_class()
  File "/Users/bolataldiyar/Desktop/password_manager/conf/venv/lib/python3.8/site-packages/rest_framework/generics.py", line 122, in get_serializer_class
    assert self.serializer_class is not None, (
AssertionError: 'ProfileViewSet' should either include a `serializer_class` attribute, or override the `get_serializer_class()` method.
2021-05-06 14:05:41,557 -- ERROR:40 -- Internal Server Error: /auth/profile/login
Traceback (most recent call last):
  File "/Users/bolataldiyar/Desktop/password_manager/conf/venv/lib/python3.8/site-packages/django/core/handlers/exception.py", line 34, in inner
    response = get_response(request)
  File "/Users/bolataldiyar/Desktop/password_manager/conf/venv/lib/python3.8/site-packages/django/utils/deprecation.py", line 93, in __call__
    response = self.process_request(request)
  File "/Users/bolataldiyar/Desktop/password_manager/conf/venv/lib/python3.8/site-packages/django/middleware/common.py", line 53, in process_request
    path = self.get_full_path_with_slash(request)
  File "/Users/bolataldiyar/Desktop/password_manager/conf/venv/lib/python3.8/site-packages/django/middleware/common.py", line 86, in get_full_path_with_slash
    raise RuntimeError(
RuntimeError: You called this URL via POST, but the URL doesn't end in a slash and you have APPEND_SLASH set. Django can't redirect to the slash URL while maintaining POST data. Change your form to point to 127.0.0.1:8000/auth/profile/login/ (note the trailing slash), or set APPEND_SLASH=False in your Django settings.
2021-05-06 14:05:48,229 -- WARNING:30 -- Method Not Allowed: /auth/profile/login/
2021-05-06 14:08:10,407 -- INFO:20 -- /Users/bolataldiyar/Desktop/password_manager/conf/auth_/views.py changed, reloading.
2021-05-06 14:08:11,076 -- INFO:20 -- Watching for file changes with StatReloader
2021-05-06 14:08:12,826 -- INFO:20 -- /Users/bolataldiyar/Desktop/password_manager/conf/auth_/serializers.py changed, reloading.
2021-05-06 14:08:13,171 -- INFO:20 -- Watching for file changes with StatReloader
2021-05-06 14:08:14,827 -- WARNING:30 -- Method Not Allowed: /auth/profile/login/
2021-05-06 14:08:15,534 -- WARNING:30 -- Method Not Allowed: /auth/profile/login/
2021-05-06 14:08:19,453 -- WARNING:30 -- Not Found: /auth/profile/login/
2021-05-06 14:08:34,976 -- ERROR:40 -- Internal Server Error: /auth/profile/upload_photo/
Traceback (most recent call last):
  File "/Users/bolataldiyar/Desktop/password_manager/conf/venv/lib/python3.8/site-packages/django/core/handlers/exception.py", line 34, in inner
    response = get_response(request)
  File "/Users/bolataldiyar/Desktop/password_manager/conf/venv/lib/python3.8/site-packages/django/core/handlers/base.py", line 115, in _get_response
    response = self.process_exception_by_middleware(e, request)
  File "/Users/bolataldiyar/Desktop/password_manager/conf/venv/lib/python3.8/site-packages/django/core/handlers/base.py", line 113, in _get_response
    response = wrapped_callback(request, *callback_args, **callback_kwargs)
  File "/Users/bolataldiyar/Desktop/password_manager/conf/venv/lib/python3.8/site-packages/django/views/decorators/csrf.py", line 54, in wrapped_view
    return view_func(*args, **kwargs)
  File "/Users/bolataldiyar/Desktop/password_manager/conf/venv/lib/python3.8/site-packages/rest_framework/viewsets.py", line 125, in view
    return self.dispatch(request, *args, **kwargs)
  File "/Users/bolataldiyar/Desktop/password_manager/conf/venv/lib/python3.8/site-packages/rest_framework/views.py", line 509, in dispatch
    response = self.handle_exception(exc)
  File "/Users/bolataldiyar/Desktop/password_manager/conf/venv/lib/python3.8/site-packages/rest_framework/views.py", line 469, in handle_exception
    self.raise_uncaught_exception(exc)
  File "/Users/bolataldiyar/Desktop/password_manager/conf/venv/lib/python3.8/site-packages/rest_framework/views.py", line 480, in raise_uncaught_exception
    raise exc
  File "/Users/bolataldiyar/Desktop/password_manager/conf/venv/lib/python3.8/site-packages/rest_framework/views.py", line 506, in dispatch
    response = handler(request, *args, **kwargs)
TypeError: upload_photo() takes 1 positional argument but 2 were given
2021-05-06 14:10:25,846 -- INFO:20 -- /Users/bolataldiyar/Desktop/password_manager/conf/auth_/views.py changed, reloading.
2021-05-06 14:10:26,252 -- INFO:20 -- Watching for file changes with StatReloader
2021-05-06 14:10:39,798 -- INFO:20 -- /Users/bolataldiyar/Desktop/password_manager/conf/auth_/views.py changed, reloading.
2021-05-06 14:10:40,168 -- INFO:20 -- Watching for file changes with StatReloader
2021-05-06 14:10:56,924 -- INFO:20 -- /Users/bolataldiyar/Desktop/password_manager/conf/auth_/views.py changed, reloading.
2021-05-06 14:10:57,366 -- INFO:20 -- Watching for file changes with StatReloader
2021-05-06 14:14:07,139 -- INFO:20 -- /Users/bolataldiyar/Desktop/password_manager/conf/auth_/views.py changed, reloading.
2021-05-06 14:14:07,554 -- INFO:20 -- Watching for file changes with StatReloader
2021-05-06 14:16:28,007 -- INFO:20 -- /Users/bolataldiyar/Desktop/password_manager/conf/auth_/views.py changed, reloading.
2021-05-06 14:16:28,389 -- INFO:20 -- Watching for file changes with StatReloader
2021-05-06 14:16:29,018 -- ERROR:40 -- Internal Server Error: /auth/profile/upload_photo/
Traceback (most recent call last):
  File "/Users/bolataldiyar/Desktop/password_manager/conf/venv/lib/python3.8/site-packages/django/core/handlers/exception.py", line 34, in inner
    response = get_response(request)
  File "/Users/bolataldiyar/Desktop/password_manager/conf/venv/lib/python3.8/site-packages/django/core/handlers/base.py", line 115, in _get_response
    response = self.process_exception_by_middleware(e, request)
  File "/Users/bolataldiyar/Desktop/password_manager/conf/venv/lib/python3.8/site-packages/django/core/handlers/base.py", line 113, in _get_response
    response = wrapped_callback(request, *callback_args, **callback_kwargs)
  File "/Users/bolataldiyar/Desktop/password_manager/conf/venv/lib/python3.8/site-packages/django/views/decorators/csrf.py", line 54, in wrapped_view
    return view_func(*args, **kwargs)
  File "/Users/bolataldiyar/Desktop/password_manager/conf/venv/lib/python3.8/site-packages/rest_framework/viewsets.py", line 125, in view
    return self.dispatch(request, *args, **kwargs)
  File "/Users/bolataldiyar/Desktop/password_manager/conf/venv/lib/python3.8/site-packages/rest_framework/views.py", line 509, in dispatch
    response = self.handle_exception(exc)
  File "/Users/bolataldiyar/Desktop/password_manager/conf/venv/lib/python3.8/site-packages/rest_framework/views.py", line 469, in handle_exception
    self.raise_uncaught_exception(exc)
  File "/Users/bolataldiyar/Desktop/password_manager/conf/venv/lib/python3.8/site-packages/rest_framework/views.py", line 480, in raise_uncaught_exception
    raise exc
  File "/Users/bolataldiyar/Desktop/password_manager/conf/venv/lib/python3.8/site-packages/rest_framework/views.py", line 506, in dispatch
    response = handler(request, *args, **kwargs)
  File "/Users/bolataldiyar/Desktop/password_manager/conf/auth_/views.py", line 53, in upload_photo
    print(request.data.image)
AttributeError: 'QueryDict' object has no attribute 'image'
2021-05-06 14:16:47,157 -- ERROR:40 -- Internal Server Error: /auth/profile/upload_photo/
Traceback (most recent call last):
  File "/Users/bolataldiyar/Desktop/password_manager/conf/venv/lib/python3.8/site-packages/django/core/handlers/exception.py", line 34, in inner
    response = get_response(request)
  File "/Users/bolataldiyar/Desktop/password_manager/conf/venv/lib/python3.8/site-packages/django/core/handlers/base.py", line 115, in _get_response
    response = self.process_exception_by_middleware(e, request)
  File "/Users/bolataldiyar/Desktop/password_manager/conf/venv/lib/python3.8/site-packages/django/core/handlers/base.py", line 113, in _get_response
    response = wrapped_callback(request, *callback_args, **callback_kwargs)
  File "/Users/bolataldiyar/Desktop/password_manager/conf/venv/lib/python3.8/site-packages/django/views/decorators/csrf.py", line 54, in wrapped_view
    return view_func(*args, **kwargs)
  File "/Users/bolataldiyar/Desktop/password_manager/conf/venv/lib/python3.8/site-packages/rest_framework/viewsets.py", line 125, in view
    return self.dispatch(request, *args, **kwargs)
  File "/Users/bolataldiyar/Desktop/password_manager/conf/venv/lib/python3.8/site-packages/rest_framework/views.py", line 509, in dispatch
    response = self.handle_exception(exc)
  File "/Users/bolataldiyar/Desktop/password_manager/conf/venv/lib/python3.8/site-packages/rest_framework/views.py", line 469, in handle_exception
    self.raise_uncaught_exception(exc)
  File "/Users/bolataldiyar/Desktop/password_manager/conf/venv/lib/python3.8/site-packages/rest_framework/views.py", line 480, in raise_uncaught_exception
    raise exc
  File "/Users/bolataldiyar/Desktop/password_manager/conf/venv/lib/python3.8/site-packages/rest_framework/views.py", line 506, in dispatch
    response = handler(request, *args, **kwargs)
  File "/Users/bolataldiyar/Desktop/password_manager/conf/auth_/views.py", line 53, in upload_photo
    print(request.data)
AttributeError: 'QueryDict' object has no attribute 'image'
2021-05-06 14:16:47,231 -- INFO:20 -- /Users/bolataldiyar/Desktop/password_manager/conf/auth_/views.py changed, reloading.
2021-05-06 14:16:47,872 -- INFO:20 -- Watching for file changes with StatReloader
2021-05-06 14:17:07,182 -- INFO:20 -- /Users/bolataldiyar/Desktop/password_manager/conf/auth_/views.py changed, reloading.
2021-05-06 14:17:07,531 -- INFO:20 -- Watching for file changes with StatReloader
2021-05-06 14:17:23,308 -- INFO:20 -- /Users/bolataldiyar/Desktop/password_manager/conf/auth_/views.py changed, reloading.
2021-05-06 14:17:23,671 -- INFO:20 -- Watching for file changes with StatReloader
2021-05-06 14:18:14,152 -- INFO:20 -- /Users/bolataldiyar/Desktop/password_manager/conf/auth_/views.py changed, reloading.
2021-05-06 14:18:14,534 -- INFO:20 -- Watching for file changes with StatReloader
2021-05-06 14:18:16,367 -- ERROR:40 -- Internal Server Error: /auth/profile/upload_photo/
Traceback (most recent call last):
  File "/Users/bolataldiyar/Desktop/password_manager/conf/venv/lib/python3.8/site-packages/django/db/backends/utils.py", line 84, in _execute
    return self.cursor.execute(sql, params)
  File "/Users/bolataldiyar/Desktop/password_manager/conf/venv/lib/python3.8/site-packages/django/db/backends/sqlite3/base.py", line 383, in execute
    return Database.Cursor.execute(self, query, params)
sqlite3.OperationalError: no such column: auth__profile.photo

The above exception was the direct cause of the following exception:

Traceback (most recent call last):
  File "/Users/bolataldiyar/Desktop/password_manager/conf/venv/lib/python3.8/site-packages/django/core/handlers/exception.py", line 34, in inner
    response = get_response(request)
  File "/Users/bolataldiyar/Desktop/password_manager/conf/venv/lib/python3.8/site-packages/django/core/handlers/base.py", line 115, in _get_response
    response = self.process_exception_by_middleware(e, request)
  File "/Users/bolataldiyar/Desktop/password_manager/conf/venv/lib/python3.8/site-packages/django/core/handlers/base.py", line 113, in _get_response
    response = wrapped_callback(request, *callback_args, **callback_kwargs)
  File "/Users/bolataldiyar/Desktop/password_manager/conf/venv/lib/python3.8/site-packages/django/views/decorators/csrf.py", line 54, in wrapped_view
    return view_func(*args, **kwargs)
  File "/Users/bolataldiyar/Desktop/password_manager/conf/venv/lib/python3.8/site-packages/rest_framework/viewsets.py", line 125, in view
    return self.dispatch(request, *args, **kwargs)
  File "/Users/bolataldiyar/Desktop/password_manager/conf/venv/lib/python3.8/site-packages/rest_framework/views.py", line 509, in dispatch
    response = self.handle_exception(exc)
  File "/Users/bolataldiyar/Desktop/password_manager/conf/venv/lib/python3.8/site-packages/rest_framework/views.py", line 469, in handle_exception
    self.raise_uncaught_exception(exc)
  File "/Users/bolataldiyar/Desktop/password_manager/conf/venv/lib/python3.8/site-packages/rest_framework/views.py", line 480, in raise_uncaught_exception
    raise exc
  File "/Users/bolataldiyar/Desktop/password_manager/conf/venv/lib/python3.8/site-packages/rest_framework/views.py", line 506, in dispatch
    response = handler(request, *args, **kwargs)
  File "/Users/bolataldiyar/Desktop/password_manager/conf/auth_/views.py", line 54, in upload_photo
    profile = Profile.objects.get(user=request.user)
  File "/Users/bolataldiyar/Desktop/password_manager/conf/venv/lib/python3.8/site-packages/django/db/models/manager.py", line 82, in manager_method
    return getattr(self.get_queryset(), name)(*args, **kwargs)
  File "/Users/bolataldiyar/Desktop/password_manager/conf/venv/lib/python3.8/site-packages/django/db/models/query.py", line 402, in get
    num = len(clone)
  File "/Users/bolataldiyar/Desktop/password_manager/conf/venv/lib/python3.8/site-packages/django/db/models/query.py", line 256, in __len__
    self._fetch_all()
  File "/Users/bolataldiyar/Desktop/password_manager/conf/venv/lib/python3.8/site-packages/django/db/models/query.py", line 1242, in _fetch_all
    self._result_cache = list(self._iterable_class(self))
  File "/Users/bolataldiyar/Desktop/password_manager/conf/venv/lib/python3.8/site-packages/django/db/models/query.py", line 55, in __iter__
    results = compiler.execute_sql(chunked_fetch=self.chunked_fetch, chunk_size=self.chunk_size)
  File "/Users/bolataldiyar/Desktop/password_manager/conf/venv/lib/python3.8/site-packages/django/db/models/sql/compiler.py", line 1100, in execute_sql
    cursor.execute(sql, params)
  File "/Users/bolataldiyar/Desktop/password_manager/conf/venv/lib/python3.8/site-packages/django/db/backends/utils.py", line 99, in execute
    return super().execute(sql, params)
  File "/Users/bolataldiyar/Desktop/password_manager/conf/venv/lib/python3.8/site-packages/django/db/backends/utils.py", line 67, in execute
    return self._execute_with_wrappers(sql, params, many=False, executor=self._execute)
  File "/Users/bolataldiyar/Desktop/password_manager/conf/venv/lib/python3.8/site-packages/django/db/backends/utils.py", line 76, in _execute_with_wrappers
    return executor(sql, params, many, context)
  File "/Users/bolataldiyar/Desktop/password_manager/conf/venv/lib/python3.8/site-packages/django/db/backends/utils.py", line 84, in _execute
    return self.cursor.execute(sql, params)
  File "/Users/bolataldiyar/Desktop/password_manager/conf/venv/lib/python3.8/site-packages/django/db/utils.py", line 89, in __exit__
    raise dj_exc_value.with_traceback(traceback) from exc_value
  File "/Users/bolataldiyar/Desktop/password_manager/conf/venv/lib/python3.8/site-packages/django/db/backends/utils.py", line 84, in _execute
    return self.cursor.execute(sql, params)
  File "/Users/bolataldiyar/Desktop/password_manager/conf/venv/lib/python3.8/site-packages/django/db/backends/sqlite3/base.py", line 383, in execute
    return Database.Cursor.execute(self, query, params)
django.db.utils.OperationalError: no such column: auth__profile.photo
2021-05-06 14:18:18,135 -- ERROR:40 -- Internal Server Error: /auth/profile/upload_photo/
Traceback (most recent call last):
  File "/Users/bolataldiyar/Desktop/password_manager/conf/venv/lib/python3.8/site-packages/django/db/backends/utils.py", line 84, in _execute
    return self.cursor.execute(sql, params)
  File "/Users/bolataldiyar/Desktop/password_manager/conf/venv/lib/python3.8/site-packages/django/db/backends/sqlite3/base.py", line 383, in execute
    return Database.Cursor.execute(self, query, params)
sqlite3.OperationalError: no such column: auth__profile.photo

The above exception was the direct cause of the following exception:

Traceback (most recent call last):
  File "/Users/bolataldiyar/Desktop/password_manager/conf/venv/lib/python3.8/site-packages/django/core/handlers/exception.py", line 34, in inner
    response = get_response(request)
  File "/Users/bolataldiyar/Desktop/password_manager/conf/venv/lib/python3.8/site-packages/django/core/handlers/base.py", line 115, in _get_response
    response = self.process_exception_by_middleware(e, request)
  File "/Users/bolataldiyar/Desktop/password_manager/conf/venv/lib/python3.8/site-packages/django/core/handlers/base.py", line 113, in _get_response
    response = wrapped_callback(request, *callback_args, **callback_kwargs)
  File "/Users/bolataldiyar/Desktop/password_manager/conf/venv/lib/python3.8/site-packages/django/views/decorators/csrf.py", line 54, in wrapped_view
    return view_func(*args, **kwargs)
  File "/Users/bolataldiyar/Desktop/password_manager/conf/venv/lib/python3.8/site-packages/rest_framework/viewsets.py", line 125, in view
    return self.dispatch(request, *args, **kwargs)
  File "/Users/bolataldiyar/Desktop/password_manager/conf/venv/lib/python3.8/site-packages/rest_framework/views.py", line 509, in dispatch
    response = self.handle_exception(exc)
  File "/Users/bolataldiyar/Desktop/password_manager/conf/venv/lib/python3.8/site-packages/rest_framework/views.py", line 469, in handle_exception
    self.raise_uncaught_exception(exc)
  File "/Users/bolataldiyar/Desktop/password_manager/conf/venv/lib/python3.8/site-packages/rest_framework/views.py", line 480, in raise_uncaught_exception
    raise exc
  File "/Users/bolataldiyar/Desktop/password_manager/conf/venv/lib/python3.8/site-packages/rest_framework/views.py", line 506, in dispatch
    response = handler(request, *args, **kwargs)
  File "/Users/bolataldiyar/Desktop/password_manager/conf/auth_/views.py", line 54, in upload_photo
    profile = Profile.objects.get(user=request.user)
  File "/Users/bolataldiyar/Desktop/password_manager/conf/venv/lib/python3.8/site-packages/django/db/models/manager.py", line 82, in manager_method
    return getattr(self.get_queryset(), name)(*args, **kwargs)
  File "/Users/bolataldiyar/Desktop/password_manager/conf/venv/lib/python3.8/site-packages/django/db/models/query.py", line 402, in get
    num = len(clone)
  File "/Users/bolataldiyar/Desktop/password_manager/conf/venv/lib/python3.8/site-packages/django/db/models/query.py", line 256, in __len__
    self._fetch_all()
  File "/Users/bolataldiyar/Desktop/password_manager/conf/venv/lib/python3.8/site-packages/django/db/models/query.py", line 1242, in _fetch_all
    self._result_cache = list(self._iterable_class(self))
  File "/Users/bolataldiyar/Desktop/password_manager/conf/venv/lib/python3.8/site-packages/django/db/models/query.py", line 55, in __iter__
    results = compiler.execute_sql(chunked_fetch=self.chunked_fetch, chunk_size=self.chunk_size)
  File "/Users/bolataldiyar/Desktop/password_manager/conf/venv/lib/python3.8/site-packages/django/db/models/sql/compiler.py", line 1100, in execute_sql
    cursor.execute(sql, params)
  File "/Users/bolataldiyar/Desktop/password_manager/conf/venv/lib/python3.8/site-packages/django/db/backends/utils.py", line 99, in execute
    return super().execute(sql, params)
  File "/Users/bolataldiyar/Desktop/password_manager/conf/venv/lib/python3.8/site-packages/django/db/backends/utils.py", line 67, in execute
    return self._execute_with_wrappers(sql, params, many=False, executor=self._execute)
  File "/Users/bolataldiyar/Desktop/password_manager/conf/venv/lib/python3.8/site-packages/django/db/backends/utils.py", line 76, in _execute_with_wrappers
    return executor(sql, params, many, context)
  File "/Users/bolataldiyar/Desktop/password_manager/conf/venv/lib/python3.8/site-packages/django/db/backends/utils.py", line 84, in _execute
    return self.cursor.execute(sql, params)
  File "/Users/bolataldiyar/Desktop/password_manager/conf/venv/lib/python3.8/site-packages/django/db/utils.py", line 89, in __exit__
    raise dj_exc_value.with_traceback(traceback) from exc_value
  File "/Users/bolataldiyar/Desktop/password_manager/conf/venv/lib/python3.8/site-packages/django/db/backends/utils.py", line 84, in _execute
    return self.cursor.execute(sql, params)
  File "/Users/bolataldiyar/Desktop/password_manager/conf/venv/lib/python3.8/site-packages/django/db/backends/sqlite3/base.py", line 383, in execute
    return Database.Cursor.execute(self, query, params)
django.db.utils.OperationalError: no such column: auth__profile.photo
2021-05-06 14:18:39,794 -- INFO:20 -- Watching for file changes with StatReloader
2021-05-06 14:18:42,833 -- ERROR:40 -- Internal Server Error: /auth/profile/upload_photo/
Traceback (most recent call last):
  File "/Users/bolataldiyar/Desktop/password_manager/conf/venv/lib/python3.8/site-packages/django/core/handlers/exception.py", line 34, in inner
    response = get_response(request)
  File "/Users/bolataldiyar/Desktop/password_manager/conf/venv/lib/python3.8/site-packages/django/core/handlers/base.py", line 115, in _get_response
    response = self.process_exception_by_middleware(e, request)
  File "/Users/bolataldiyar/Desktop/password_manager/conf/venv/lib/python3.8/site-packages/django/core/handlers/base.py", line 113, in _get_response
    response = wrapped_callback(request, *callback_args, **callback_kwargs)
  File "/Users/bolataldiyar/Desktop/password_manager/conf/venv/lib/python3.8/site-packages/django/views/decorators/csrf.py", line 54, in wrapped_view
    return view_func(*args, **kwargs)
  File "/Users/bolataldiyar/Desktop/password_manager/conf/venv/lib/python3.8/site-packages/rest_framework/viewsets.py", line 125, in view
    return self.dispatch(request, *args, **kwargs)
  File "/Users/bolataldiyar/Desktop/password_manager/conf/venv/lib/python3.8/site-packages/rest_framework/views.py", line 509, in dispatch
    response = self.handle_exception(exc)
  File "/Users/bolataldiyar/Desktop/password_manager/conf/venv/lib/python3.8/site-packages/rest_framework/views.py", line 469, in handle_exception
    self.raise_uncaught_exception(exc)
  File "/Users/bolataldiyar/Desktop/password_manager/conf/venv/lib/python3.8/site-packages/rest_framework/views.py", line 480, in raise_uncaught_exception
    raise exc
  File "/Users/bolataldiyar/Desktop/password_manager/conf/venv/lib/python3.8/site-packages/rest_framework/views.py", line 506, in dispatch
    response = handler(request, *args, **kwargs)
  File "/Users/bolataldiyar/Desktop/password_manager/conf/auth_/views.py", line 54, in upload_photo
    profile = Profile.objects.get(user=request.user)
  File "/Users/bolataldiyar/Desktop/password_manager/conf/venv/lib/python3.8/site-packages/django/db/models/manager.py", line 82, in manager_method
    return getattr(self.get_queryset(), name)(*args, **kwargs)
  File "/Users/bolataldiyar/Desktop/password_manager/conf/venv/lib/python3.8/site-packages/django/db/models/query.py", line 406, in get
    raise self.model.DoesNotExist(
auth_.models.Profile.DoesNotExist: Profile matching query does not exist.
2021-05-06 14:18:44,737 -- ERROR:40 -- Internal Server Error: /auth/profile/upload_photo/
Traceback (most recent call last):
  File "/Users/bolataldiyar/Desktop/password_manager/conf/venv/lib/python3.8/site-packages/django/core/handlers/exception.py", line 34, in inner
    response = get_response(request)
  File "/Users/bolataldiyar/Desktop/password_manager/conf/venv/lib/python3.8/site-packages/django/core/handlers/base.py", line 115, in _get_response
    response = self.process_exception_by_middleware(e, request)
  File "/Users/bolataldiyar/Desktop/password_manager/conf/venv/lib/python3.8/site-packages/django/core/handlers/base.py", line 113, in _get_response
    response = wrapped_callback(request, *callback_args, **callback_kwargs)
  File "/Users/bolataldiyar/Desktop/password_manager/conf/venv/lib/python3.8/site-packages/django/views/decorators/csrf.py", line 54, in wrapped_view
    return view_func(*args, **kwargs)
  File "/Users/bolataldiyar/Desktop/password_manager/conf/venv/lib/python3.8/site-packages/rest_framework/viewsets.py", line 125, in view
    return self.dispatch(request, *args, **kwargs)
  File "/Users/bolataldiyar/Desktop/password_manager/conf/venv/lib/python3.8/site-packages/rest_framework/views.py", line 509, in dispatch
    response = self.handle_exception(exc)
  File "/Users/bolataldiyar/Desktop/password_manager/conf/venv/lib/python3.8/site-packages/rest_framework/views.py", line 469, in handle_exception
    self.raise_uncaught_exception(exc)
  File "/Users/bolataldiyar/Desktop/password_manager/conf/venv/lib/python3.8/site-packages/rest_framework/views.py", line 480, in raise_uncaught_exception
    raise exc
  File "/Users/bolataldiyar/Desktop/password_manager/conf/venv/lib/python3.8/site-packages/rest_framework/views.py", line 506, in dispatch
    response = handler(request, *args, **kwargs)
  File "/Users/bolataldiyar/Desktop/password_manager/conf/auth_/views.py", line 54, in upload_photo
    profile = Profile.objects.get(user=request.user)
  File "/Users/bolataldiyar/Desktop/password_manager/conf/venv/lib/python3.8/site-packages/django/db/models/manager.py", line 82, in manager_method
    return getattr(self.get_queryset(), name)(*args, **kwargs)
  File "/Users/bolataldiyar/Desktop/password_manager/conf/venv/lib/python3.8/site-packages/django/db/models/query.py", line 406, in get
    raise self.model.DoesNotExist(
auth_.models.Profile.DoesNotExist: Profile matching query does not exist.
2021-05-06 14:18:45,428 -- ERROR:40 -- Internal Server Error: /auth/profile/upload_photo/
Traceback (most recent call last):
  File "/Users/bolataldiyar/Desktop/password_manager/conf/venv/lib/python3.8/site-packages/django/core/handlers/exception.py", line 34, in inner
    response = get_response(request)
  File "/Users/bolataldiyar/Desktop/password_manager/conf/venv/lib/python3.8/site-packages/django/core/handlers/base.py", line 115, in _get_response
    response = self.process_exception_by_middleware(e, request)
  File "/Users/bolataldiyar/Desktop/password_manager/conf/venv/lib/python3.8/site-packages/django/core/handlers/base.py", line 113, in _get_response
    response = wrapped_callback(request, *callback_args, **callback_kwargs)
  File "/Users/bolataldiyar/Desktop/password_manager/conf/venv/lib/python3.8/site-packages/django/views/decorators/csrf.py", line 54, in wrapped_view
    return view_func(*args, **kwargs)
  File "/Users/bolataldiyar/Desktop/password_manager/conf/venv/lib/python3.8/site-packages/rest_framework/viewsets.py", line 125, in view
    return self.dispatch(request, *args, **kwargs)
  File "/Users/bolataldiyar/Desktop/password_manager/conf/venv/lib/python3.8/site-packages/rest_framework/views.py", line 509, in dispatch
    response = self.handle_exception(exc)
  File "/Users/bolataldiyar/Desktop/password_manager/conf/venv/lib/python3.8/site-packages/rest_framework/views.py", line 469, in handle_exception
    self.raise_uncaught_exception(exc)
  File "/Users/bolataldiyar/Desktop/password_manager/conf/venv/lib/python3.8/site-packages/rest_framework/views.py", line 480, in raise_uncaught_exception
    raise exc
  File "/Users/bolataldiyar/Desktop/password_manager/conf/venv/lib/python3.8/site-packages/rest_framework/views.py", line 506, in dispatch
    response = handler(request, *args, **kwargs)
  File "/Users/bolataldiyar/Desktop/password_manager/conf/auth_/views.py", line 54, in upload_photo
    profile = Profile.objects.get(user=request.user)
  File "/Users/bolataldiyar/Desktop/password_manager/conf/venv/lib/python3.8/site-packages/django/db/models/manager.py", line 82, in manager_method
    return getattr(self.get_queryset(), name)(*args, **kwargs)
  File "/Users/bolataldiyar/Desktop/password_manager/conf/venv/lib/python3.8/site-packages/django/db/models/query.py", line 406, in get
    raise self.model.DoesNotExist(
auth_.models.Profile.DoesNotExist: Profile matching query does not exist.
2021-05-06 14:18:53,111 -- WARNING:30 -- Not Acceptable: /auth/create_user
2021-05-06 14:18:55,653 -- WARNING:30 -- Not Acceptable: /auth/create_user
2021-05-07 08:21:03,813 -- INFO:20 -- Watching for file changes with StatReloader
2021-05-07 09:02:54,455 -- INFO:20 -- Watching for file changes with StatReloader
2021-05-07 09:03:12,818 -- INFO:20 -- Watching for file changes with StatReloader
2021-05-07 09:05:16,916 -- INFO:20 -- /Users/bolataldiyar/Desktop/password_manager/conf/auth_/views.py changed, reloading.
2021-05-07 09:05:17,273 -- INFO:20 -- Watching for file changes with StatReloader
2021-05-07 09:47:34,163 -- INFO:20 -- /Users/bolataldiyar/Desktop/password_manager/conf/password_manager/models.py changed, reloading.
2021-05-07 09:47:34,990 -- INFO:20 -- Watching for file changes with StatReloader
2021-05-07 09:49:23,347 -- INFO:20 -- Watching for file changes with StatReloader
2021-05-08 10:36:00,286 -- INFO:20 -- Watching for file changes with StatReloader
2021-05-08 10:36:11,656 -- INFO:20 -- Watching for file changes with StatReloader
2021-05-08 10:36:23,706 -- WARNING:30 -- Bad Request: /auth/login/
2021-05-08 10:36:46,931 -- INFO:20 -- /Users/bolataldiyar/Desktop/password_manager/conf/conf/settings.py changed, reloading.
2021-05-08 10:36:47,330 -- INFO:20 -- Watching for file changes with StatReloader
2021-05-08 10:36:49,903 -- INFO:20 -- /Users/bolataldiyar/Desktop/password_manager/conf/conf/settings.py changed, reloading.
2021-05-08 10:36:50,292 -- INFO:20 -- Watching for file changes with StatReloader
2021-05-08 10:52:09,850 -- INFO:20 -- /Users/bolataldiyar/Desktop/password_manager/conf/password_manager/views.py changed, reloading.
2021-05-08 10:52:10,508 -- INFO:20 -- Watching for file changes with StatReloader
2021-05-08 10:52:38,263 -- INFO:20 -- /Users/bolataldiyar/Desktop/password_manager/conf/password_manager/views.py changed, reloading.
2021-05-08 10:52:38,701 -- INFO:20 -- Watching for file changes with StatReloader
2021-05-08 10:52:46,908 -- INFO:20 -- /Users/bolataldiyar/Desktop/password_manager/conf/password_manager/views.py changed, reloading.
2021-05-08 10:52:47,295 -- INFO:20 -- Watching for file changes with StatReloader
2021-05-08 10:53:34,590 -- INFO:20 -- /Users/bolataldiyar/Desktop/password_manager/conf/password_manager/views.py changed, reloading.
2021-05-08 10:53:34,977 -- INFO:20 -- Watching for file changes with StatReloader
2021-05-08 10:53:51,012 -- ERROR:40 -- Internal Server Error: /password_manager/create_password_collection
Traceback (most recent call last):
  File "/Users/bolataldiyar/Desktop/password_manager/conf/venv/lib/python3.8/site-packages/django/core/handlers/exception.py", line 34, in inner
    response = get_response(request)
  File "/Users/bolataldiyar/Desktop/password_manager/conf/venv/lib/python3.8/site-packages/django/core/handlers/base.py", line 115, in _get_response
    response = self.process_exception_by_middleware(e, request)
  File "/Users/bolataldiyar/Desktop/password_manager/conf/venv/lib/python3.8/site-packages/django/core/handlers/base.py", line 113, in _get_response
    response = wrapped_callback(request, *callback_args, **callback_kwargs)
  File "/Users/bolataldiyar/Desktop/password_manager/conf/venv/lib/python3.8/site-packages/django/views/decorators/csrf.py", line 54, in wrapped_view
    return view_func(*args, **kwargs)
  File "/Users/bolataldiyar/Desktop/password_manager/conf/venv/lib/python3.8/site-packages/django/views/generic/base.py", line 71, in view
    return self.dispatch(request, *args, **kwargs)
  File "/Users/bolataldiyar/Desktop/password_manager/conf/venv/lib/python3.8/site-packages/rest_framework/views.py", line 509, in dispatch
    response = self.handle_exception(exc)
  File "/Users/bolataldiyar/Desktop/password_manager/conf/venv/lib/python3.8/site-packages/rest_framework/views.py", line 469, in handle_exception
    self.raise_uncaught_exception(exc)
  File "/Users/bolataldiyar/Desktop/password_manager/conf/venv/lib/python3.8/site-packages/rest_framework/views.py", line 480, in raise_uncaught_exception
    raise exc
  File "/Users/bolataldiyar/Desktop/password_manager/conf/venv/lib/python3.8/site-packages/rest_framework/views.py", line 506, in dispatch
    response = handler(request, *args, **kwargs)
  File "/Users/bolataldiyar/Desktop/password_manager/conf/venv/lib/python3.8/site-packages/rest_framework/decorators.py", line 50, in handler
    return func(*args, **kwargs)
  File "/Users/bolataldiyar/Desktop/password_manager/conf/password_manager/views.py", line 33, in create_password_collection
    if serializer.is_valid():
  File "/Users/bolataldiyar/Desktop/password_manager/conf/venv/lib/python3.8/site-packages/rest_framework/serializers.py", line 220, in is_valid
    self._validated_data = self.run_validation(self.initial_data)
  File "/Users/bolataldiyar/Desktop/password_manager/conf/venv/lib/python3.8/site-packages/rest_framework/serializers.py", line 419, in run_validation
    value = self.to_internal_value(data)
  File "/Users/bolataldiyar/Desktop/password_manager/conf/venv/lib/python3.8/site-packages/rest_framework/serializers.py", line 472, in to_internal_value
    for field in fields:
  File "/Users/bolataldiyar/Desktop/password_manager/conf/venv/lib/python3.8/site-packages/rest_framework/serializers.py", line 355, in _writable_fields
    for field in self.fields.values():
  File "/Users/bolataldiyar/Desktop/password_manager/conf/venv/lib/python3.8/site-packages/django/utils/functional.py", line 80, in __get__
    res = instance.__dict__[self.name] = self.func(instance)
  File "/Users/bolataldiyar/Desktop/password_manager/conf/venv/lib/python3.8/site-packages/rest_framework/serializers.py", line 349, in fields
    for key, value in self.get_fields().items():
  File "/Users/bolataldiyar/Desktop/password_manager/conf/venv/lib/python3.8/site-packages/rest_framework/serializers.py", line 1009, in get_fields
    assert hasattr(self.Meta, 'model'), (
AssertionError: Class PasswordCollectionSerializer missing "Meta.model" attribute
2021-05-08 10:53:58,748 -- ERROR:40 -- Internal Server Error: /password_manager/create_password_collection
Traceback (most recent call last):
  File "/Users/bolataldiyar/Desktop/password_manager/conf/venv/lib/python3.8/site-packages/django/core/handlers/exception.py", line 34, in inner
    response = get_response(request)
  File "/Users/bolataldiyar/Desktop/password_manager/conf/venv/lib/python3.8/site-packages/django/core/handlers/base.py", line 115, in _get_response
    response = self.process_exception_by_middleware(e, request)
  File "/Users/bolataldiyar/Desktop/password_manager/conf/venv/lib/python3.8/site-packages/django/core/handlers/base.py", line 113, in _get_response
    response = wrapped_callback(request, *callback_args, **callback_kwargs)
  File "/Users/bolataldiyar/Desktop/password_manager/conf/venv/lib/python3.8/site-packages/django/views/decorators/csrf.py", line 54, in wrapped_view
    return view_func(*args, **kwargs)
  File "/Users/bolataldiyar/Desktop/password_manager/conf/venv/lib/python3.8/site-packages/django/views/generic/base.py", line 71, in view
    return self.dispatch(request, *args, **kwargs)
  File "/Users/bolataldiyar/Desktop/password_manager/conf/venv/lib/python3.8/site-packages/rest_framework/views.py", line 509, in dispatch
    response = self.handle_exception(exc)
  File "/Users/bolataldiyar/Desktop/password_manager/conf/venv/lib/python3.8/site-packages/rest_framework/views.py", line 469, in handle_exception
    self.raise_uncaught_exception(exc)
  File "/Users/bolataldiyar/Desktop/password_manager/conf/venv/lib/python3.8/site-packages/rest_framework/views.py", line 480, in raise_uncaught_exception
    raise exc
  File "/Users/bolataldiyar/Desktop/password_manager/conf/venv/lib/python3.8/site-packages/rest_framework/views.py", line 506, in dispatch
    response = handler(request, *args, **kwargs)
  File "/Users/bolataldiyar/Desktop/password_manager/conf/venv/lib/python3.8/site-packages/rest_framework/decorators.py", line 50, in handler
    return func(*args, **kwargs)
  File "/Users/bolataldiyar/Desktop/password_manager/conf/password_manager/views.py", line 33, in create_password_collection
    if serializer.is_valid():
  File "/Users/bolataldiyar/Desktop/password_manager/conf/venv/lib/python3.8/site-packages/rest_framework/serializers.py", line 220, in is_valid
    self._validated_data = self.run_validation(self.initial_data)
  File "/Users/bolataldiyar/Desktop/password_manager/conf/venv/lib/python3.8/site-packages/rest_framework/serializers.py", line 419, in run_validation
    value = self.to_internal_value(data)
  File "/Users/bolataldiyar/Desktop/password_manager/conf/venv/lib/python3.8/site-packages/rest_framework/serializers.py", line 472, in to_internal_value
    for field in fields:
  File "/Users/bolataldiyar/Desktop/password_manager/conf/venv/lib/python3.8/site-packages/rest_framework/serializers.py", line 355, in _writable_fields
    for field in self.fields.values():
  File "/Users/bolataldiyar/Desktop/password_manager/conf/venv/lib/python3.8/site-packages/django/utils/functional.py", line 80, in __get__
    res = instance.__dict__[self.name] = self.func(instance)
  File "/Users/bolataldiyar/Desktop/password_manager/conf/venv/lib/python3.8/site-packages/rest_framework/serializers.py", line 349, in fields
    for key, value in self.get_fields().items():
  File "/Users/bolataldiyar/Desktop/password_manager/conf/venv/lib/python3.8/site-packages/rest_framework/serializers.py", line 1009, in get_fields
    assert hasattr(self.Meta, 'model'), (
AssertionError: Class PasswordCollectionSerializer missing "Meta.model" attribute
2021-05-08 10:54:44,019 -- INFO:20 -- /Users/bolataldiyar/Desktop/password_manager/conf/password_manager/serializers.py changed, reloading.
2021-05-08 10:54:44,386 -- INFO:20 -- Watching for file changes with StatReloader
2021-05-08 10:55:35,521 -- ERROR:40 -- Internal Server Error: /password_manager/website_password/
Traceback (most recent call last):
  File "/Users/bolataldiyar/Desktop/password_manager/conf/venv/lib/python3.8/site-packages/django/core/handlers/exception.py", line 34, in inner
    response = get_response(request)
  File "/Users/bolataldiyar/Desktop/password_manager/conf/venv/lib/python3.8/site-packages/django/core/handlers/base.py", line 115, in _get_response
    response = self.process_exception_by_middleware(e, request)
  File "/Users/bolataldiyar/Desktop/password_manager/conf/venv/lib/python3.8/site-packages/django/core/handlers/base.py", line 113, in _get_response
    response = wrapped_callback(request, *callback_args, **callback_kwargs)
  File "/Users/bolataldiyar/Desktop/password_manager/conf/venv/lib/python3.8/site-packages/django/views/decorators/csrf.py", line 54, in wrapped_view
    return view_func(*args, **kwargs)
  File "/Users/bolataldiyar/Desktop/password_manager/conf/venv/lib/python3.8/site-packages/rest_framework/viewsets.py", line 125, in view
    return self.dispatch(request, *args, **kwargs)
  File "/Users/bolataldiyar/Desktop/password_manager/conf/venv/lib/python3.8/site-packages/rest_framework/views.py", line 509, in dispatch
    response = self.handle_exception(exc)
  File "/Users/bolataldiyar/Desktop/password_manager/conf/venv/lib/python3.8/site-packages/rest_framework/views.py", line 469, in handle_exception
    self.raise_uncaught_exception(exc)
  File "/Users/bolataldiyar/Desktop/password_manager/conf/venv/lib/python3.8/site-packages/rest_framework/views.py", line 480, in raise_uncaught_exception
    raise exc
  File "/Users/bolataldiyar/Desktop/password_manager/conf/venv/lib/python3.8/site-packages/rest_framework/views.py", line 506, in dispatch
    response = handler(request, *args, **kwargs)
  File "/Users/bolataldiyar/Desktop/password_manager/conf/venv/lib/python3.8/site-packages/rest_framework/mixins.py", line 18, in create
    serializer.is_valid(raise_exception=True)
  File "/Users/bolataldiyar/Desktop/password_manager/conf/venv/lib/python3.8/site-packages/rest_framework/serializers.py", line 220, in is_valid
    self._validated_data = self.run_validation(self.initial_data)
  File "/Users/bolataldiyar/Desktop/password_manager/conf/venv/lib/python3.8/site-packages/rest_framework/serializers.py", line 419, in run_validation
    value = self.to_internal_value(data)
  File "/Users/bolataldiyar/Desktop/password_manager/conf/venv/lib/python3.8/site-packages/rest_framework/serializers.py", line 476, in to_internal_value
    validated_value = field.run_validation(primitive_value)
  File "/Users/bolataldiyar/Desktop/password_manager/conf/venv/lib/python3.8/site-packages/rest_framework/serializers.py", line 419, in run_validation
    value = self.to_internal_value(data)
  File "/Users/bolataldiyar/Desktop/password_manager/conf/venv/lib/python3.8/site-packages/rest_framework/serializers.py", line 472, in to_internal_value
    for field in fields:
  File "/Users/bolataldiyar/Desktop/password_manager/conf/venv/lib/python3.8/site-packages/rest_framework/serializers.py", line 355, in _writable_fields
    for field in self.fields.values():
  File "/Users/bolataldiyar/Desktop/password_manager/conf/venv/lib/python3.8/site-packages/django/utils/functional.py", line 80, in __get__
    res = instance.__dict__[self.name] = self.func(instance)
  File "/Users/bolataldiyar/Desktop/password_manager/conf/venv/lib/python3.8/site-packages/rest_framework/serializers.py", line 349, in fields
    for key, value in self.get_fields().items():
  File "/Users/bolataldiyar/Desktop/password_manager/conf/venv/lib/python3.8/site-packages/rest_framework/serializers.py", line 1009, in get_fields
    assert hasattr(self.Meta, 'model'), (
AssertionError: Class PasswordCollectionsSerializer missing "Meta.model" attribute
2021-05-08 10:56:24,913 -- INFO:20 -- /Users/bolataldiyar/Desktop/password_manager/conf/password_manager/serializers.py changed, reloading.
2021-05-08 10:56:25,340 -- INFO:20 -- Watching for file changes with StatReloader
2021-05-08 10:56:26,128 -- INFO:20 -- WebSitePassword created, ID: WebSitePassword object (1)
2021-05-08 10:57:00,551 -- INFO:20 -- /Users/bolataldiyar/Desktop/password_manager/conf/password_manager/views.py changed, reloading.
2021-05-08 10:57:00,945 -- INFO:20 -- Watching for file changes with StatReloader
2021-05-08 10:57:04,602 -- INFO:20 -- WebSitePassword created, ID: WebSitePassword object (2)
2021-05-08 10:57:15,609 -- INFO:20 -- /Users/bolataldiyar/Desktop/password_manager/conf/password_manager/views.py changed, reloading.
2021-05-08 10:57:15,986 -- INFO:20 -- Watching for file changes with StatReloader
2021-05-08 10:59:39,103 -- INFO:20 -- /Users/bolataldiyar/Desktop/password_manager/conf/password_manager/views.py changed, reloading.
2021-05-08 10:59:39,452 -- INFO:20 -- Watching for file changes with StatReloader
2021-05-08 11:13:57,492 -- INFO:20 -- Watching for file changes with StatReloader
2021-05-08 11:14:36,235 -- INFO:20 -- WebSitePassword created, ID: WebSitePassword object (3)
2021-05-08 11:14:54,614 -- INFO:20 -- /Users/bolataldiyar/Desktop/password_manager/conf/password_manager/serializers.py changed, reloading.
2021-05-08 11:14:55,067 -- INFO:20 -- Watching for file changes with StatReloader
2021-05-08 11:14:58,345 -- ERROR:40 -- Internal Server Error: /password_manager/website_password/
Traceback (most recent call last):
  File "/Users/bolataldiyar/Desktop/password_manager/conf/venv/lib/python3.8/site-packages/django/core/handlers/exception.py", line 34, in inner
    response = get_response(request)
  File "/Users/bolataldiyar/Desktop/password_manager/conf/venv/lib/python3.8/site-packages/django/core/handlers/base.py", line 115, in _get_response
    response = self.process_exception_by_middleware(e, request)
  File "/Users/bolataldiyar/Desktop/password_manager/conf/venv/lib/python3.8/site-packages/django/core/handlers/base.py", line 113, in _get_response
    response = wrapped_callback(request, *callback_args, **callback_kwargs)
  File "/Users/bolataldiyar/Desktop/password_manager/conf/venv/lib/python3.8/site-packages/django/views/decorators/csrf.py", line 54, in wrapped_view
    return view_func(*args, **kwargs)
  File "/Users/bolataldiyar/Desktop/password_manager/conf/venv/lib/python3.8/site-packages/rest_framework/viewsets.py", line 125, in view
    return self.dispatch(request, *args, **kwargs)
  File "/Users/bolataldiyar/Desktop/password_manager/conf/venv/lib/python3.8/site-packages/rest_framework/views.py", line 509, in dispatch
    response = self.handle_exception(exc)
  File "/Users/bolataldiyar/Desktop/password_manager/conf/venv/lib/python3.8/site-packages/rest_framework/views.py", line 469, in handle_exception
    self.raise_uncaught_exception(exc)
  File "/Users/bolataldiyar/Desktop/password_manager/conf/venv/lib/python3.8/site-packages/rest_framework/views.py", line 480, in raise_uncaught_exception
    raise exc
  File "/Users/bolataldiyar/Desktop/password_manager/conf/venv/lib/python3.8/site-packages/rest_framework/views.py", line 506, in dispatch
    response = handler(request, *args, **kwargs)
  File "/Users/bolataldiyar/Desktop/password_manager/conf/venv/lib/python3.8/site-packages/rest_framework/mixins.py", line 18, in create
    serializer.is_valid(raise_exception=True)
  File "/Users/bolataldiyar/Desktop/password_manager/conf/venv/lib/python3.8/site-packages/rest_framework/serializers.py", line 220, in is_valid
    self._validated_data = self.run_validation(self.initial_data)
  File "/Users/bolataldiyar/Desktop/password_manager/conf/venv/lib/python3.8/site-packages/rest_framework/serializers.py", line 423, in run_validation
    assert value is not None, '.validate() should return the validated data'
AssertionError: .validate() should return the validated data
2021-05-08 11:15:08,659 -- INFO:20 -- /Users/bolataldiyar/Desktop/password_manager/conf/password_manager/serializers.py changed, reloading.
2021-05-08 11:15:09,035 -- INFO:20 -- Watching for file changes with StatReloader
2021-05-08 11:18:08,482 -- INFO:20 -- /Users/bolataldiyar/Desktop/password_manager/conf/password_manager/serializers.py changed, reloading.
2021-05-08 11:18:08,913 -- INFO:20 -- Watching for file changes with StatReloader
2021-05-08 11:18:27,830 -- INFO:20 -- /Users/bolataldiyar/Desktop/password_manager/conf/password_manager/serializers.py changed, reloading.
2021-05-08 11:18:28,214 -- INFO:20 -- Watching for file changes with StatReloader
2021-05-08 11:19:14,126 -- INFO:20 -- /Users/bolataldiyar/Desktop/password_manager/conf/password_manager/serializers.py changed, reloading.
2021-05-08 11:19:14,480 -- INFO:20 -- Watching for file changes with StatReloader
2021-05-08 11:19:16,862 -- INFO:20 -- WebSitePassword created, ID: WebSitePassword object (4)
2021-05-08 11:19:49,826 -- INFO:20 -- /Users/bolataldiyar/Desktop/password_manager/conf/password_manager/serializers.py changed, reloading.
2021-05-08 11:19:50,205 -- INFO:20 -- Watching for file changes with StatReloader
2021-05-08 11:20:54,833 -- INFO:20 -- /Users/bolataldiyar/Desktop/password_manager/conf/password_manager/serializers.py changed, reloading.
2021-05-08 11:20:55,255 -- INFO:20 -- Watching for file changes with StatReloader
2021-05-08 11:24:07,966 -- INFO:20 -- /Users/bolataldiyar/Desktop/password_manager/conf/password_manager/serializers.py changed, reloading.
2021-05-08 11:24:08,325 -- INFO:20 -- Watching for file changes with StatReloader
2021-05-08 11:26:23,767 -- INFO:20 -- /Users/bolataldiyar/Desktop/password_manager/conf/password_manager/serializers.py changed, reloading.
2021-05-08 11:26:24,156 -- INFO:20 -- Watching for file changes with StatReloader
2021-05-08 11:26:34,813 -- ERROR:40 -- Internal Server Error: /password_manager/create_password_collection
2021-05-08 11:30:43,195 -- INFO:20 -- /Users/bolataldiyar/Desktop/password_manager/conf/auth_/serializers.py changed, reloading.
2021-05-08 11:30:43,643 -- INFO:20 -- Watching for file changes with StatReloader
2021-05-08 11:30:45,128 -- INFO:20 -- /Users/bolataldiyar/Desktop/password_manager/conf/auth_/serializers.py changed, reloading.
2021-05-08 11:30:45,482 -- INFO:20 -- Watching for file changes with StatReloader
2021-05-08 11:32:41,252 -- INFO:20 -- /Users/bolataldiyar/Desktop/password_manager/conf/auth_/signals.py changed, reloading.
2021-05-08 11:32:41,895 -- INFO:20 -- Watching for file changes with StatReloader
2021-05-08 11:32:49,419 -- ERROR:40 -- Internal Server Error: /auth/create_user
Traceback (most recent call last):
  File "/Users/bolataldiyar/Desktop/password_manager/conf/venv/lib/python3.8/site-packages/django/core/handlers/exception.py", line 34, in inner
    response = get_response(request)
  File "/Users/bolataldiyar/Desktop/password_manager/conf/venv/lib/python3.8/site-packages/django/core/handlers/base.py", line 115, in _get_response
    response = self.process_exception_by_middleware(e, request)
  File "/Users/bolataldiyar/Desktop/password_manager/conf/venv/lib/python3.8/site-packages/django/core/handlers/base.py", line 113, in _get_response
    response = wrapped_callback(request, *callback_args, **callback_kwargs)
  File "/Users/bolataldiyar/Desktop/password_manager/conf/venv/lib/python3.8/site-packages/django/views/decorators/csrf.py", line 54, in wrapped_view
    return view_func(*args, **kwargs)
  File "/Users/bolataldiyar/Desktop/password_manager/conf/venv/lib/python3.8/site-packages/django/views/generic/base.py", line 71, in view
    return self.dispatch(request, *args, **kwargs)
  File "/Users/bolataldiyar/Desktop/password_manager/conf/venv/lib/python3.8/site-packages/rest_framework/views.py", line 509, in dispatch
    response = self.handle_exception(exc)
  File "/Users/bolataldiyar/Desktop/password_manager/conf/venv/lib/python3.8/site-packages/rest_framework/views.py", line 469, in handle_exception
    self.raise_uncaught_exception(exc)
  File "/Users/bolataldiyar/Desktop/password_manager/conf/venv/lib/python3.8/site-packages/rest_framework/views.py", line 480, in raise_uncaught_exception
    raise exc
  File "/Users/bolataldiyar/Desktop/password_manager/conf/venv/lib/python3.8/site-packages/rest_framework/views.py", line 506, in dispatch
    response = handler(request, *args, **kwargs)
  File "/Users/bolataldiyar/Desktop/password_manager/conf/venv/lib/python3.8/site-packages/rest_framework/decorators.py", line 50, in handler
    return func(*args, **kwargs)
  File "/Users/bolataldiyar/Desktop/password_manager/conf/auth_/views.py", line 20, in create_user
    user = User.objects.create_user(username=request.data.get('username'),
  File "/Users/bolataldiyar/Desktop/password_manager/conf/auth_/models.py", line 25, in create_user
    return self._create_user(email, password, **extra_fields)
  File "/Users/bolataldiyar/Desktop/password_manager/conf/auth_/models.py", line 21, in _create_user
    user.save(using=self._db)
  File "/Users/bolataldiyar/Desktop/password_manager/conf/venv/lib/python3.8/site-packages/django/contrib/auth/base_user.py", line 66, in save
    super().save(*args, **kwargs)
  File "/Users/bolataldiyar/Desktop/password_manager/conf/venv/lib/python3.8/site-packages/django/db/models/base.py", line 740, in save
    self.save_base(using=using, force_insert=force_insert,
  File "/Users/bolataldiyar/Desktop/password_manager/conf/venv/lib/python3.8/site-packages/django/db/models/base.py", line 788, in save_base
    post_save.send(
  File "/Users/bolataldiyar/Desktop/password_manager/conf/venv/lib/python3.8/site-packages/django/dispatch/dispatcher.py", line 173, in send
    return [
  File "/Users/bolataldiyar/Desktop/password_manager/conf/venv/lib/python3.8/site-packages/django/dispatch/dispatcher.py", line 174, in <listcomp>
    (receiver, receiver(signal=self, sender=sender, **named))
  File "/Users/bolataldiyar/Desktop/password_manager/conf/auth_/signals.py", line 21, in user_created
    serializer = ProfileSerializer(user=instance, country='KZ')
  File "/Users/bolataldiyar/Desktop/password_manager/conf/venv/lib/python3.8/site-packages/rest_framework/serializers.py", line 115, in __init__
    super().__init__(**kwargs)
TypeError: __init__() got an unexpected keyword argument 'user'
2021-05-08 11:33:20,262 -- INFO:20 -- /Users/bolataldiyar/Desktop/password_manager/conf/auth_/signals.py changed, reloading.
2021-05-08 11:33:20,780 -- INFO:20 -- Watching for file changes with StatReloader
2021-05-08 11:33:24,322 -- INFO:20 -- /Users/bolataldiyar/Desktop/password_manager/conf/auth_/signals.py changed, reloading.
2021-05-08 11:33:24,885 -- INFO:20 -- Watching for file changes with StatReloader
2021-05-08 11:33:28,014 -- WARNING:30 -- Not Acceptable: /auth/create_user
2021-05-08 11:48:11,173 -- INFO:20 -- /Users/bolataldiyar/Desktop/password_manager/conf/auth_/serializers.py changed, reloading.
2021-05-08 11:49:16,559 -- INFO:20 -- Watching for file changes with StatReloader
2021-05-08 11:49:42,923 -- INFO:20 -- /Users/bolataldiyar/Desktop/password_manager/conf/auth_/signals.py changed, reloading.
2021-05-08 11:49:43,349 -- INFO:20 -- Watching for file changes with StatReloader
2021-05-08 11:49:47,023 -- INFO:20 -- /Users/bolataldiyar/Desktop/password_manager/conf/auth_/signals.py changed, reloading.
2021-05-08 11:49:47,393 -- INFO:20 -- Watching for file changes with StatReloader
2021-05-08 11:59:00,349 -- INFO:20 -- Watching for file changes with StatReloader
2021-05-08 11:59:03,369 -- WARNING:30 -- Not Found: /
2021-05-08 11:59:03,411 -- WARNING:30 -- Not Found: /favicon.ico
2021-05-08 11:59:06,419 -- WARNING:30 -- Not Found: /
2021-05-08 11:59:07,229 -- WARNING:30 -- Not Found: /favicon.ico
2021-05-08 12:00:33,043 -- INFO:20 -- Watching for file changes with StatReloader
2021-05-08 12:06:47,295 -- INFO:20 -- /Users/bolataldiyar/Desktop/password_manager/conf/auth_/models.py changed, reloading.
2021-05-08 12:06:47,652 -- INFO:20 -- Watching for file changes with StatReloader
2021-05-08 12:07:43,302 -- INFO:20 -- /Users/bolataldiyar/Desktop/password_manager/conf/auth_/models.py changed, reloading.
2021-05-08 12:07:43,647 -- INFO:20 -- Watching for file changes with StatReloader
2021-05-08 12:09:24,991 -- INFO:20 -- /Users/bolataldiyar/Desktop/password_manager/conf/auth_/models.py changed, reloading.
2021-05-08 12:09:25,693 -- INFO:20 -- Watching for file changes with StatReloader
2021-05-08 12:10:05,355 -- INFO:20 -- /Users/bolataldiyar/Desktop/password_manager/conf/auth_/models.py changed, reloading.
2021-05-08 12:10:05,707 -- INFO:20 -- Watching for file changes with StatReloader
2021-05-08 12:10:27,147 -- INFO:20 -- Watching for file changes with StatReloader
2021-05-08 12:11:25,705 -- INFO:20 -- Watching for file changes with StatReloader
2021-05-08 12:11:51,579 -- WARNING:30 -- Not Found: /favicon.ico
2021-05-08 12:16:15,483 -- INFO:20 -- /Users/bolataldiyar/Desktop/password_manager/conf/auth_/admin.py changed, reloading.
2021-05-08 12:16:15,849 -- INFO:20 -- Watching for file changes with StatReloader
2021-05-08 12:16:22,975 -- WARNING:30 -- Not Found: /favicon.ico
2021-05-08 12:16:24,663 -- WARNING:30 -- Not Found: /favicon.ico
2021-05-08 12:17:51,888 -- INFO:20 -- /Users/bolataldiyar/Desktop/password_manager/conf/password_manager/admin.py changed, reloading.
2021-05-08 12:17:52,240 -- INFO:20 -- Watching for file changes with StatReloader
2021-05-08 12:18:00,382 -- WARNING:30 -- Not Found: /favicon.ico
2021-05-08 12:18:02,432 -- WARNING:30 -- Not Found: /favicon.ico
2021-05-08 12:18:05,460 -- WARNING:30 -- Not Found: /favicon.ico
2021-05-08 12:18:07,868 -- WARNING:30 -- Not Found: /favicon.ico
2021-05-08 12:18:09,658 -- WARNING:30 -- Not Found: /favicon.ico
2021-05-08 12:25:02,799 -- WARNING:30 -- Not Found: /favicon.ico
2021-05-08 12:25:05,421 -- WARNING:30 -- Not Found: /favicon.ico
2021-05-08 12:25:11,506 -- WARNING:30 -- Not Found: /favicon.ico
2021-05-08 12:25:29,381 -- INFO:20 -- token deleted
2021-05-08 12:26:17,854 -- WARNING:30 -- Not Found: /favicon.ico
2021-05-08 12:27:06,363 -- WARNING:30 -- Not Found: /favicon.ico
2021-05-08 12:28:41,345 -- INFO:20 -- WebSitePassword created, ID: WebSitePassword object (5)
2021-05-08 12:28:48,283 -- WARNING:30 -- Not Found: /favicon.ico
2021-05-08 12:29:25,173 -- INFO:20 -- WifiPassword created, ID: WifiPassword object (1)
2021-05-08 12:29:31,010 -- WARNING:30 -- Not Found: /favicon.ico
2021-05-08 12:29:48,108 -- ERROR:40 -- Internal Server Error: /password_manager/website_bookmark/
Traceback (most recent call last):
  File "/Users/bolataldiyar/Desktop/password_manager/conf/venv/lib/python3.8/site-packages/django/core/handlers/exception.py", line 34, in inner
    response = get_response(request)
  File "/Users/bolataldiyar/Desktop/password_manager/conf/venv/lib/python3.8/site-packages/django/core/handlers/base.py", line 115, in _get_response
    response = self.process_exception_by_middleware(e, request)
  File "/Users/bolataldiyar/Desktop/password_manager/conf/venv/lib/python3.8/site-packages/django/core/handlers/base.py", line 113, in _get_response
    response = wrapped_callback(request, *callback_args, **callback_kwargs)
  File "/Users/bolataldiyar/Desktop/password_manager/conf/venv/lib/python3.8/site-packages/django/views/decorators/csrf.py", line 54, in wrapped_view
    return view_func(*args, **kwargs)
  File "/Users/bolataldiyar/Desktop/password_manager/conf/venv/lib/python3.8/site-packages/rest_framework/viewsets.py", line 125, in view
    return self.dispatch(request, *args, **kwargs)
  File "/Users/bolataldiyar/Desktop/password_manager/conf/venv/lib/python3.8/site-packages/rest_framework/views.py", line 509, in dispatch
    response = self.handle_exception(exc)
  File "/Users/bolataldiyar/Desktop/password_manager/conf/venv/lib/python3.8/site-packages/rest_framework/views.py", line 469, in handle_exception
    self.raise_uncaught_exception(exc)
  File "/Users/bolataldiyar/Desktop/password_manager/conf/venv/lib/python3.8/site-packages/rest_framework/views.py", line 480, in raise_uncaught_exception
    raise exc
  File "/Users/bolataldiyar/Desktop/password_manager/conf/venv/lib/python3.8/site-packages/rest_framework/views.py", line 506, in dispatch
    response = handler(request, *args, **kwargs)
  File "/Users/bolataldiyar/Desktop/password_manager/conf/venv/lib/python3.8/site-packages/rest_framework/mixins.py", line 19, in create
    self.perform_create(serializer)
  File "/Users/bolataldiyar/Desktop/password_manager/conf/password_manager/views.py", line 95, in perform_create
    serializer.save()
  File "/Users/bolataldiyar/Desktop/password_manager/conf/venv/lib/python3.8/site-packages/rest_framework/serializers.py", line 205, in save
    self.instance = self.create(validated_data)
  File "/Users/bolataldiyar/Desktop/password_manager/conf/password_manager/serializers.py", line 78, in create
    website_password = WebSitePassword.objects.get(name=validated_data['website_password']['name'])
  File "/Users/bolataldiyar/Desktop/password_manager/conf/venv/lib/python3.8/site-packages/django/db/models/manager.py", line 82, in manager_method
    return getattr(self.get_queryset(), name)(*args, **kwargs)
  File "/Users/bolataldiyar/Desktop/password_manager/conf/venv/lib/python3.8/site-packages/django/db/models/query.py", line 406, in get
    raise self.model.DoesNotExist(
password_manager.models.WebSitePassword.DoesNotExist: WebSitePassword matching query does not exist.
2021-05-08 12:31:46,996 -- WARNING:30 -- Not Found: /favicon.ico
2021-05-08 12:32:01,786 -- INFO:20 -- /Users/bolataldiyar/Desktop/password_manager/conf/password_manager/serializers.py changed, reloading.
2021-05-08 12:32:02,153 -- INFO:20 -- Watching for file changes with StatReloader
2021-05-08 12:32:06,436 -- ERROR:40 -- Internal Server Error: /password_manager/website_bookmark/
Traceback (most recent call last):
  File "/Users/bolataldiyar/Desktop/password_manager/conf/venv/lib/python3.8/site-packages/django/core/handlers/exception.py", line 34, in inner
    response = get_response(request)
  File "/Users/bolataldiyar/Desktop/password_manager/conf/venv/lib/python3.8/site-packages/django/core/handlers/base.py", line 115, in _get_response
    response = self.process_exception_by_middleware(e, request)
  File "/Users/bolataldiyar/Desktop/password_manager/conf/venv/lib/python3.8/site-packages/django/core/handlers/base.py", line 113, in _get_response
    response = wrapped_callback(request, *callback_args, **callback_kwargs)
  File "/Users/bolataldiyar/Desktop/password_manager/conf/venv/lib/python3.8/site-packages/django/views/decorators/csrf.py", line 54, in wrapped_view
    return view_func(*args, **kwargs)
  File "/Users/bolataldiyar/Desktop/password_manager/conf/venv/lib/python3.8/site-packages/rest_framework/viewsets.py", line 125, in view
    return self.dispatch(request, *args, **kwargs)
  File "/Users/bolataldiyar/Desktop/password_manager/conf/venv/lib/python3.8/site-packages/rest_framework/views.py", line 509, in dispatch
    response = self.handle_exception(exc)
  File "/Users/bolataldiyar/Desktop/password_manager/conf/venv/lib/python3.8/site-packages/rest_framework/views.py", line 469, in handle_exception
    self.raise_uncaught_exception(exc)
  File "/Users/bolataldiyar/Desktop/password_manager/conf/venv/lib/python3.8/site-packages/rest_framework/views.py", line 480, in raise_uncaught_exception
    raise exc
  File "/Users/bolataldiyar/Desktop/password_manager/conf/venv/lib/python3.8/site-packages/rest_framework/views.py", line 506, in dispatch
    response = handler(request, *args, **kwargs)
  File "/Users/bolataldiyar/Desktop/password_manager/conf/venv/lib/python3.8/site-packages/rest_framework/mixins.py", line 19, in create
    self.perform_create(serializer)
  File "/Users/bolataldiyar/Desktop/password_manager/conf/password_manager/views.py", line 95, in perform_create
    serializer.save()
  File "/Users/bolataldiyar/Desktop/password_manager/conf/venv/lib/python3.8/site-packages/rest_framework/serializers.py", line 205, in save
    self.instance = self.create(validated_data)
  File "/Users/bolataldiyar/Desktop/password_manager/conf/password_manager/serializers.py", line 78, in create
    website_password = WebSitePassword.objects.get(id=validated_data['website_password']['id'])
KeyError: 'id'
2021-05-08 12:32:25,550 -- ERROR:40 -- Internal Server Error: /password_manager/website_bookmark/
Traceback (most recent call last):
  File "/Users/bolataldiyar/Desktop/password_manager/conf/venv/lib/python3.8/site-packages/django/core/handlers/exception.py", line 34, in inner
    response = get_response(request)
  File "/Users/bolataldiyar/Desktop/password_manager/conf/venv/lib/python3.8/site-packages/django/core/handlers/base.py", line 115, in _get_response
    response = self.process_exception_by_middleware(e, request)
  File "/Users/bolataldiyar/Desktop/password_manager/conf/venv/lib/python3.8/site-packages/django/core/handlers/base.py", line 113, in _get_response
    response = wrapped_callback(request, *callback_args, **callback_kwargs)
  File "/Users/bolataldiyar/Desktop/password_manager/conf/venv/lib/python3.8/site-packages/django/views/decorators/csrf.py", line 54, in wrapped_view
    return view_func(*args, **kwargs)
  File "/Users/bolataldiyar/Desktop/password_manager/conf/venv/lib/python3.8/site-packages/rest_framework/viewsets.py", line 125, in view
    return self.dispatch(request, *args, **kwargs)
  File "/Users/bolataldiyar/Desktop/password_manager/conf/venv/lib/python3.8/site-packages/rest_framework/views.py", line 509, in dispatch
    response = self.handle_exception(exc)
  File "/Users/bolataldiyar/Desktop/password_manager/conf/venv/lib/python3.8/site-packages/rest_framework/views.py", line 469, in handle_exception
    self.raise_uncaught_exception(exc)
  File "/Users/bolataldiyar/Desktop/password_manager/conf/venv/lib/python3.8/site-packages/rest_framework/views.py", line 480, in raise_uncaught_exception
    raise exc
  File "/Users/bolataldiyar/Desktop/password_manager/conf/venv/lib/python3.8/site-packages/rest_framework/views.py", line 506, in dispatch
    response = handler(request, *args, **kwargs)
  File "/Users/bolataldiyar/Desktop/password_manager/conf/venv/lib/python3.8/site-packages/rest_framework/mixins.py", line 19, in create
    self.perform_create(serializer)
  File "/Users/bolataldiyar/Desktop/password_manager/conf/password_manager/views.py", line 95, in perform_create
    serializer.save()
  File "/Users/bolataldiyar/Desktop/password_manager/conf/venv/lib/python3.8/site-packages/rest_framework/serializers.py", line 205, in save
    self.instance = self.create(validated_data)
  File "/Users/bolataldiyar/Desktop/password_manager/conf/password_manager/serializers.py", line 78, in create
    website_password = WebSitePassword.objects.get(id=validated_data['website_password']['id'])
KeyError: 'id'
2021-05-08 12:32:38,276 -- INFO:20 -- Watching for file changes with StatReloader
2021-05-08 12:32:42,369 -- ERROR:40 -- Internal Server Error: /password_manager/website_bookmark/
Traceback (most recent call last):
  File "/Users/bolataldiyar/Desktop/password_manager/conf/venv/lib/python3.8/site-packages/django/core/handlers/exception.py", line 34, in inner
    response = get_response(request)
  File "/Users/bolataldiyar/Desktop/password_manager/conf/venv/lib/python3.8/site-packages/django/core/handlers/base.py", line 115, in _get_response
    response = self.process_exception_by_middleware(e, request)
  File "/Users/bolataldiyar/Desktop/password_manager/conf/venv/lib/python3.8/site-packages/django/core/handlers/base.py", line 113, in _get_response
    response = wrapped_callback(request, *callback_args, **callback_kwargs)
  File "/Users/bolataldiyar/Desktop/password_manager/conf/venv/lib/python3.8/site-packages/django/views/decorators/csrf.py", line 54, in wrapped_view
    return view_func(*args, **kwargs)
  File "/Users/bolataldiyar/Desktop/password_manager/conf/venv/lib/python3.8/site-packages/rest_framework/viewsets.py", line 125, in view
    return self.dispatch(request, *args, **kwargs)
  File "/Users/bolataldiyar/Desktop/password_manager/conf/venv/lib/python3.8/site-packages/rest_framework/views.py", line 509, in dispatch
    response = self.handle_exception(exc)
  File "/Users/bolataldiyar/Desktop/password_manager/conf/venv/lib/python3.8/site-packages/rest_framework/views.py", line 469, in handle_exception
    self.raise_uncaught_exception(exc)
  File "/Users/bolataldiyar/Desktop/password_manager/conf/venv/lib/python3.8/site-packages/rest_framework/views.py", line 480, in raise_uncaught_exception
    raise exc
  File "/Users/bolataldiyar/Desktop/password_manager/conf/venv/lib/python3.8/site-packages/rest_framework/views.py", line 506, in dispatch
    response = handler(request, *args, **kwargs)
  File "/Users/bolataldiyar/Desktop/password_manager/conf/venv/lib/python3.8/site-packages/rest_framework/mixins.py", line 19, in create
    self.perform_create(serializer)
  File "/Users/bolataldiyar/Desktop/password_manager/conf/password_manager/views.py", line 95, in perform_create
    serializer.save()
  File "/Users/bolataldiyar/Desktop/password_manager/conf/venv/lib/python3.8/site-packages/rest_framework/serializers.py", line 205, in save
    self.instance = self.create(validated_data)
  File "/Users/bolataldiyar/Desktop/password_manager/conf/password_manager/serializers.py", line 78, in create
    website_password = WebSitePassword.objects.get(id=validated_data['website_password']['id'])
KeyError: 'id'
2021-05-08 12:32:51,899 -- INFO:20 -- /Users/bolataldiyar/Desktop/password_manager/conf/password_manager/serializers.py changed, reloading.
2021-05-08 12:32:52,284 -- INFO:20 -- Watching for file changes with StatReloader
2021-05-08 12:32:54,168 -- ERROR:40 -- Internal Server Error: /password_manager/website_bookmark/
Traceback (most recent call last):
  File "/Users/bolataldiyar/Desktop/password_manager/conf/venv/lib/python3.8/site-packages/django/core/handlers/exception.py", line 34, in inner
    response = get_response(request)
  File "/Users/bolataldiyar/Desktop/password_manager/conf/venv/lib/python3.8/site-packages/django/core/handlers/base.py", line 115, in _get_response
    response = self.process_exception_by_middleware(e, request)
  File "/Users/bolataldiyar/Desktop/password_manager/conf/venv/lib/python3.8/site-packages/django/core/handlers/base.py", line 113, in _get_response
    response = wrapped_callback(request, *callback_args, **callback_kwargs)
  File "/Users/bolataldiyar/Desktop/password_manager/conf/venv/lib/python3.8/site-packages/django/views/decorators/csrf.py", line 54, in wrapped_view
    return view_func(*args, **kwargs)
  File "/Users/bolataldiyar/Desktop/password_manager/conf/venv/lib/python3.8/site-packages/rest_framework/viewsets.py", line 125, in view
    return self.dispatch(request, *args, **kwargs)
  File "/Users/bolataldiyar/Desktop/password_manager/conf/venv/lib/python3.8/site-packages/rest_framework/views.py", line 509, in dispatch
    response = self.handle_exception(exc)
  File "/Users/bolataldiyar/Desktop/password_manager/conf/venv/lib/python3.8/site-packages/rest_framework/views.py", line 469, in handle_exception
    self.raise_uncaught_exception(exc)
  File "/Users/bolataldiyar/Desktop/password_manager/conf/venv/lib/python3.8/site-packages/rest_framework/views.py", line 480, in raise_uncaught_exception
    raise exc
  File "/Users/bolataldiyar/Desktop/password_manager/conf/venv/lib/python3.8/site-packages/rest_framework/views.py", line 506, in dispatch
    response = handler(request, *args, **kwargs)
  File "/Users/bolataldiyar/Desktop/password_manager/conf/venv/lib/python3.8/site-packages/rest_framework/mixins.py", line 19, in create
    self.perform_create(serializer)
  File "/Users/bolataldiyar/Desktop/password_manager/conf/password_manager/views.py", line 95, in perform_create
    serializer.save()
  File "/Users/bolataldiyar/Desktop/password_manager/conf/venv/lib/python3.8/site-packages/rest_framework/serializers.py", line 205, in save
    self.instance = self.create(validated_data)
  File "/Users/bolataldiyar/Desktop/password_manager/conf/password_manager/serializers.py", line 78, in create
    website_password = WebSitePassword.objects.get(name=validated_data['website_password']['name'])
  File "/Users/bolataldiyar/Desktop/password_manager/conf/venv/lib/python3.8/site-packages/django/db/models/manager.py", line 82, in manager_method
    return getattr(self.get_queryset(), name)(*args, **kwargs)
  File "/Users/bolataldiyar/Desktop/password_manager/conf/venv/lib/python3.8/site-packages/django/db/models/query.py", line 410, in get
    raise self.model.MultipleObjectsReturned(
password_manager.models.WebSitePassword.MultipleObjectsReturned: get() returned more than one WebSitePassword -- it returned 5!
2021-05-08 12:33:09,108 -- INFO:20 -- /Users/bolataldiyar/Desktop/password_manager/conf/password_manager/serializers.py changed, reloading.
2021-05-08 12:33:09,511 -- INFO:20 -- Watching for file changes with StatReloader
2021-05-08 12:33:10,957 -- INFO:20 -- Bookmark created, ID: WebSiteBookmark object (1)
